<?xml version="1.0"?>
<robot name="tobot">

  <!-- Constant for the xacro model -->

  <xacro:property name="GROUND_CLEARANCE" value="0.0335" />
  <xacro:property name="width" value="0.35" />
  <xacro:property name="bodylen" value="0.3465" />
  <xacro:property name="wheel_w" value="0.039" />
  <xacro:property name="wheel_rad" value="0.1194" />
  <xacro:property name="plat_rad" value="0.3" />
  <xacro:property name="plat_len" value="0.005" />
  <xacro:property name="HIGH_PLATFORM" value="0.15" />
  <xacro:property name="posz_laser" value="0.285" />
  <xacro:property name="posz_camera" value="0.5" />
  <xacro:property name="fwheel_rad" value="0.08276" />
  <xacro:property name="PI" value="3.1415" />

  <!--Mass values for each link in kg-->
  <xacro:property name="base_mass" value="30" />
  <xacro:property name="plat_mass" value="2" />
  <xacro:property name="actvwheel_mass" value="10" />
  <xacro:property name="psvwheel_mass" value="1" />

  <material name="black">
    <color rgba="0 0 0 1"/>
  </material>
  <material name="red">
    <color rgba="1 0 0 1"/> 
  </material>
  <material name="blue">
    <color rgba="0 0.2 0.4 1"/>
  </material>

  <!-- Actual frame and materials -->


  <!--Base_link-->
  <link name="base_link">
    <visual>
      <geometry>
         <cylinder length="${bodylen}" radius="${width}"/>
      </geometry>
      <origin rpy="0 0 0" xyz="0 0 ${GROUND_CLEARANCE}"/>
      <material name="blue"/>
    </visual>
    <collision>
      <geometry>
         <cylinder length="${bodylen}" radius="${width}"/>
      </geometry>
      <origin rpy="0 0 0" xyz="0 0 ${bodylen/2}"/>
    </collision>
    <!--Actually, I will calculate it as a thick wall cylinder-->
    <!--with inner radius=0.1 and outer radius= width -->
    <inertial>
        <mass value="${base_mass}" />
        <origin rpy="0 0 0" xyz="0 0 ${GROUND_CLEARANCE}" />
        <inertia 
          ixx="${(1/12) * base_mass * ( 3 * (0.1 * 0.1 + width * width) + bodylen)}" ixy="0.0" ixz="0.0"
          iyy="${(1/12) * base_mass * ( 3 * (0.1 * 0.1 + width * width) + bodylen)}" iyz="0.0"
          izz="${0.5 * base_mass * ( 0.1 * 0.1 + width * width)}" />
    </inertial>
  </link>
  
  <!--Left Wheel-->
  <link name="lwheel">
    <visual>
      <geometry>
        <cylinder length="${wheel_w}" radius="${wheel_rad}"/>
      </geometry>
      <origin rpy="-1.57075 0 0" xyz="0 0 ${GROUND_CLEARANCE + 0.05}"/>
      <material name="black"/>
    </visual>

    <collsion>
      <geometry>
        <cylinder length="${wheel_w}" radius="${wheel_rad}"/>
      </geometry>
      <origin rpy="-1.57075 0 0" xyz="0 0 ${GROUND_CLEARANCE + 0.05}"/>
    </collsion>
    <inertial>
        <mass value="0.010" />
        <origin rpy="-1.57075 0 0" xyz="0 0 ${GROUND_CLEARANCE + 0.05}" />
        <inertia 
          ixx="${(1/12) * actvwheel_mass * (3 * wheel_rad * wheel_rad + wheel_w * wheel_w)}" ixy="0.0" ixz="0.0"
          iyy="${(1/12) * actvwheel_mass * (3 * wheel_rad * wheel_rad + wheel_w * wheel_w)}" iyz="0.0"
          izz="${0.5 * actvwheel_mass * wheel_rad * wheel_rad }" />
    </inertial>
  </link>
  
  <joint name="base_to_lwheel" type="continuous">
    <parent link="base_link"/>
    <child link="lwheel"/>
    <axis xyz="0 1 0"/>
    <origin xyz="0 ${width} ${GROUND_CLEARANCE-(bodylen/2)}" rpy="0 0 0"/>
  </joint>
  
  <!--Right wheel-->
  <link name="rwheel">
    <visual>
      <geometry>
        <cylinder length="${wheel_w}" radius="${wheel_rad}"/>
      </geometry>
      <origin rpy="-1.57075 0 0" xyz="0 0 ${GROUND_CLEARANCE + 0.05}"/>
      <material name="black"/>
    </visual>

    <collsion>
      <geometry>
        <cylinder length="${wheel_w}" radius="${wheel_rad}"/>
      </geometry>
      <origin rpy="-1.57075 0 0" xyz="0 0 ${GROUND_CLEARANCE + 0.05}"/>
    </collsion>
    <inertial>
        <mass value="0.010" />
        <origin rpy="-1.57075 0 0" xyz="0 0 ${GROUND_CLEARANCE + 0.05}" />
        <inertia 
          ixx="${(1/12) * actvwheel_mass * (3 * wheel_rad * wheel_rad + wheel_w * wheel_w)}" ixy="0.0" ixz="0.0"
          iyy="${(1/12) * actvwheel_mass * (3 * wheel_rad * wheel_rad + wheel_w * wheel_w)}" iyz="0.0"
          izz="${0.5 * actvwheel_mass * wheel_rad * wheel_rad }" />
    </inertial>
  </link>
  
  <joint name="base_to_rwheel" type="continuous">
    <parent link="base_link"/>
    <child link="rwheel"/>
    <axis xyz="0 1 0"/>
    <origin xyz="0 ${-width} ${GROUND_CLEARANCE-(bodylen/2)}" rpy="0 0 0"/>
  </joint>
  
  <!--LASER-->
  <link name="laser">
    <visual>
      <geometry>
        <box size="0.06 0.06 0.087"/>
      </geometry>
      <origin rpy="0 0 0" xyz="0 0 0"/>
      <material name="red"/>
    </visual>
    <inertial>
        <mass value="0.270" />
        <origin xyz="0 0 0" />
        <inertia 
          ixx="2.632e-4" ixy="0" ixz="0" 
          iyy="2.632e-4" iyz="0" 
          izz="1.62e-4" />
    </inertial>
  </link>
  
  <joint name="base_laser" type="fixed">
    <parent link="base_link"/>
    <child link="laser"/>
    <origin xyz="${width + 0.07} 0 ${GROUND_CLEARANCE-bodylen+posz_laser} " rpy="0 0 0"/>
  </joint>
  
  
  <!--FRONT WHEEL-->
  <link name="fwheel">
    <visual>
      <geometry>
        <cylinder length="${wheel_w}" radius="${fwheel_rad}"/>
      </geometry>
      <origin rpy="-1.57075 0 0" xyz="0 0 ${GROUND_CLEARANCE + 0.1}"/>
      <material name="black"/>
    </visual>

    <collsion>
      <geometry>
        <cylinder length="${wheel_w}" radius="${fwheel_rad}"/>
      </geometry>
      <origin rpy="-1.57075 0 0" xyz="0 0 ${GROUND_CLEARANCE + 0.1}"/>
    </collsion>
    <inertial>
        <mass value="0.010" />
        <origin rpy="-1.57075 0 0" xyz="0 0 ${GROUND_CLEARANCE + 0.1}" />
        <inertia 
          ixx="${(1/12) * psvwheel_mass * (3 * fwheel_rad * fwheel_rad + wheel_w * wheel_w)}" ixy="0.0" ixz="0.0"
          iyy="${(1/12) * psvwheel_mass * (3 * fwheel_rad * fwheel_rad + wheel_w * wheel_w)}" iyz="0.0"
          izz="${0.5 * psvwheel_mass * fwheel_rad * fwheel_rad }" />
    </inertial>
  </link>
  
  <joint name="base_to_fwheel" type="continuous">
    <parent link="base_link"/>
    <child link="fwheel"/>
    <axis xyz="0 1 0"/>
    <origin xyz="${width} 0 ${GROUND_CLEARANCE-(bodylen/2)-(fwheel_rad)}" rpy="0 0 0"/>
  </joint>
  
  <!--BACK WHEEL-->
  <link name="bwheel">
    <visual>
      <geometry>
        <cylinder length="${wheel_w}" radius="${fwheel_rad}"/>
      </geometry>
      <origin rpy="-1.57075 0 0" xyz="0 0 ${GROUND_CLEARANCE + 0.1}"/>
      <material name="black"/>
    </visual>

    <collsion>
      <geometry>
        <cylinder length="${wheel_w}" radius="${fwheel_rad}"/>
      </geometry>
      <origin rpy="-1.57075 0 0" xyz="0 0 ${GROUND_CLEARANCE + 0.1}"/>
    </collsion>
    <inertial>
        <mass value="0.010" />
        <origin rpy="-1.57075 0 0" xyz="0 0 ${GROUND_CLEARANCE + 0.1}" />
        <inertia 
          ixx="${(1/12) * psvwheel_mass * (3 * fwheel_rad * fwheel_rad + wheel_w * wheel_w)}" ixy="0.0" ixz="0.0"
          iyy="${(1/12) * psvwheel_mass * (3 * fwheel_rad * fwheel_rad + wheel_w * wheel_w)}" iyz="0.0"
          izz="${0.5 * psvwheel_mass * fwheel_rad * fwheel_rad }" />
    </inertial>
  </link>
  
  <joint name="base_to_bwheel" type="continuous">
    <parent link="base_link"/>
    <child link="bwheel"/>
    <axis xyz="0 1 0"/>
    <origin xyz="${-width} 0 ${GROUND_CLEARANCE-(bodylen/2)-(fwheel_rad)}" rpy="0 0 0"/>
  </joint>
  
  
  <!-- PLatform qui se leve-->
  <link name="platform">
    <visual>
      <geometry>
         <cylinder length="${plat_len}" radius="${plat_rad}"/>
      </geometry>
      <origin rpy="0 0 0" xyz="0 0 ${plat_len/2}"/>
      <material name="black"/>
    </visual>
    <inertial>
        <mass value="0.001" />
        <origin xyz="${-width} 0 ${GROUND_CLEARANCE-(bodylen/2)-(fwheel_rad)}" rpy="0 0 0" />
        <inertia 
          ixx="${(1/12) * plat_mass * (3 * plat_rad * plat_rad + 0.005 * 0.005)}" ixy="0.0" ixz="0.0"
          iyy="${(1/12) * plat_mass * (3 * plat_rad * plat_rad + 0.005 * 0.005)}" iyz="0.0"
          izz="${0.5 * plat_mass * plat_rad * plat_rad }" />
    </inertial>
  </link>
  
  <joint name="base_platform" type="prismatic">
    <parent link="base_link"/>
    <child link="platform"/>
    <axis xyz="0 0 1"/>
    <limit effort="1000.0" lower="0" upper="${HIGH_PLATFORM}" velocity="0.5"/>
    <origin rpy="0 0 0" xyz="0 0 ${(bodylen/2)+GROUND_CLEARANCE}"/>
  </joint>


  <!--CAMERA-->
  <link name="camera_link">
    <visual>
      <geometry>
        <box size="0.035 0.178 0.024"/>
      </geometry>
      <origin rpy="0 0 0" xyz="0 0 0"/>
      <material name="black"/>
    </visual>
    <inertial>
        <mass value="0.200" />
        <origin xyz="0 0 0" />
        <inertia ixx="5.8083e-4" ixy="0" ixz="0" 
                 iyy="3.0833e-5" iyz="0" 
                 izz="5.9083e-4" />
   </inertial>
  </link>
  
  <joint name="camera" type="fixed">
    <parent link="base_link"/>
    <child link="camera_link"/>
    <!--<origin xyz="${width} 0 ${GROUND_CLEARANCE-bodylen+posz_camera} " rpy="0 0 0"/>-->
    <origin xyz="${width + 0.07} 0 0.05 " rpy="0 0 0"/>
  </joint>
  
</robot>
